Traceback (most recent call last):
  File "C:\ProgramData\anaconda3\envs\scientometrics\Lib\site-packages\jupyter_cache\executors\utils.py", line 58, in single_nb_execution
    executenb(
  File "C:\ProgramData\anaconda3\envs\scientometrics\Lib\site-packages\nbclient\client.py", line 1305, in execute
    return NotebookClient(nb=nb, resources=resources, km=km, **kwargs).execute()
           ^^^^^^^^^^^^^^^^^^^^^^^^^^^^^^^^^^^^^^^^^^^^^^^^^^^^^^^^^^^^^^^^^^^^^
  File "C:\ProgramData\anaconda3\envs\scientometrics\Lib\site-packages\jupyter_core\utils\__init__.py", line 173, in wrapped
    return loop.run_until_complete(inner)
           ^^^^^^^^^^^^^^^^^^^^^^^^^^^^^^
  File "C:\ProgramData\anaconda3\envs\scientometrics\Lib\asyncio\base_events.py", line 687, in run_until_complete
    return future.result()
           ^^^^^^^^^^^^^^^
  File "C:\ProgramData\anaconda3\envs\scientometrics\Lib\site-packages\nbclient\client.py", line 705, in async_execute
    await self.async_execute_cell(
  File "C:\ProgramData\anaconda3\envs\scientometrics\Lib\site-packages\nbclient\client.py", line 1058, in async_execute_cell
    await self._check_raise_for_error(cell, cell_index, exec_reply)
  File "C:\ProgramData\anaconda3\envs\scientometrics\Lib\site-packages\nbclient\client.py", line 914, in _check_raise_for_error
    raise CellExecutionError.from_cell_and_msg(cell, exec_reply_content)
nbclient.exceptions.CellExecutionError: An error occurred while executing the following cell:
------------------
glue("Echart_Sankey", Echart_Sankey, display=False)
------------------


[1;31m---------------------------------------------------------------------------[0m
[1;31mNameError[0m                                 Traceback (most recent call last)
Cell [1;32mIn[7], line 1[0m
[1;32m----> 1[0m glue([38;5;124m"[39m[38;5;124mEchart_Sankey[39m[38;5;124m"[39m, Echart_Sankey, display[38;5;241m=[39m[38;5;28;01mFalse[39;00m)

Cell [1;32mIn[3], line 13[0m, in [0;36mglueDecorator.<locals>.glueWrapper[1;34m(name, fig, **kwargs)[0m
[0;32m     10[0m [38;5;28;01mdef[39;00m [38;5;21mglueWrapper[39m(name,fig,[38;5;241m*[39m[38;5;241m*[39mkwargs):        
[0;32m     11[0m     [38;5;66;03m# Set glue() output according to fig type and build env.[39;00m
[0;32m     12[0m     [38;5;66;03m# Note buildEnv should be set globally, or passed as a kwarg.[39;00m
[1;32m---> 13[0m     [38;5;28;01mif[39;00m buildEnv [38;5;241m!=[39m [38;5;124m'[39m[38;5;124mpdf[39m[38;5;124m'[39m:
[0;32m     15[0m         [38;5;28;01mif[39;00m [38;5;124m'[39m[38;5;124mplotly[39m[38;5;124m'[39m [38;5;129;01min[39;00m [38;5;28mstr[39m([38;5;28mtype[39m(fig)):
[0;32m     16[0m             [38;5;66;03m# For Plotly may need Panel wrapper for HTML render in some cases...?[39;00m
[0;32m     17[0m             [38;5;66;03m# Without Panel some basic plot types work, but not surface plots - may also be browser-dependent?[39;00m
[0;32m     18[0m             [38;5;66;03m# Or due to maths bug, per https://jupyterbook.org/en/stable/interactive/interactive.html#plotly[39;00m
[0;32m     19[0m             [38;5;28;01mreturn[39;00m func(name, pn[38;5;241m.[39mpane[38;5;241m.[39mPlotly(fig, [38;5;241m*[39m[38;5;241m*[39mkwargs), display[38;5;241m=[39m[38;5;28;01mFalse[39;00m)

[1;31mNameError[0m: name 'buildEnv' is not defined

